Workbook
Name AnalysisDate: Dashboard!$P$3
Name BPJSKesCap: 'Company Info'!$C$44
Name CashBS: 'Balance Sheet'!$E$14
Name CFF: 'Cash Flow'!$E$36
Name CFI: 'Cash Flow'!$E$30
Name CFO: 'Cash Flow'!$E$25
Name CITRate: 'Company Info'!$C$40
Name CompanyName: 'Company Info'!$C$6
Name CompDate: 'Company Info'!$C$33
Name CompLabel: 'Company Info'!$C$49
Name ControlStatus: Controls!$E$28
Name CurLabel: 'Company Info'!$C$48
Name CutOff: 'Company Info'!$C$30
Name Fac31E: 'Company Info'!$C$41
Name Fac31ELimit: 'Company Info'!$C$42
Name FinanceCosts: 'Income Statement'!$E$21
Name FYear: 'Company Info'!$C$29
Name GrossProfit: 'Income Statement'!$E$14
Name Industry: 'Company Info'!$C$7
Name IP_CostLabel: 'Industry Profile'!$C$9
Name IP_Desc: 'Industry Profile'!$C$7
Name IP_InvLabel: 'Industry Profile'!$C$10
Name IP_Policy: 'Industry Profile'!$C$28
Name IP_RevLabel: 'Industry Profile'!$C$8
Name IP_Unit: 'Industry Profile'!$C$11
Name JPCap: 'Company Info'!$C$45
Name NetIncome: 'Income Statement'!$E$25
Name OpProfit: 'Income Statement'!$E$18
Name PBT: 'Income Statement'!$E$23
Name PEnd: 'Company Info'!$C$32
Name PeriodTitle: 'Company Info'!$C$47
Name PPh25Inst: 'Company Info'!$C$43
Name PStart: 'Company Info'!$C$31
Name R_JHTEe: Payroll!$AE$12
Name R_JHTEr: Payroll!$AE$11
Name R_JKK: Payroll!$AE$9
Name R_JKM: Payroll!$AE$10
Name R_JPEe: Payroll!$AE$14
Name R_JPEr: Payroll!$AE$13
Name R_KesEe: Payroll!$AE$8
Name R_KesEr: Payroll!$AE$7
Name Revenue: 'Income Statement'!$E$12
Name TerA_L: Payroll!$AD$18:$AD$61
Name TerA_R: Payroll!$AE$18:$AE$61
Name TerB_L: Payroll!$AF$18:$AF$57
Name TerB_R: Payroll!$AG$18:$AG$57
Name TerC_L: Payroll!$AH$18:$AH$58
Name TerC_R: Payroll!$AI$18:$AI$58
Name TotalAssets: 'Balance Sheet'!$E$26
Name TotalEquity: 'Balance Sheet'!$E$48
Name TotalLiab: 'Balance Sheet'!$E$42
Name VATEff: 'Company Info'!$C$39
Name VATFactor: 'Company Info'!$C$38
Name VATRate: 'Company Info'!$C$37
Name WHTRates: 'Company Info'!$C$56:$C$59
Name WHTTypes: 'Company Info'!$B$56:$B$59

Sheet Dashboard
B2: =UPPER(CompanyName) -> PT NUSANTARA SEJAHTERA ABADI | N2: ="Controls: "&ControlStatus -> Controls: ✔ ALL CONTROLS OK
B3: ="Financial Dashboard • "&Industry&" — "&IP_Desc&" • "&PeriodTitle -> Financial Dashboard • Retail — Retail of fashion, lifestyle & consumer electronics • For the Period from 1 January to 31 October 2026 | N3: Analysis Date ▸ | P3: 46303
B5: ☰ MAIN MENU — click a module to open it
B6: ⚙ Company Info | D6: 🏭 Industry Profile | F6: 📒 Chart of Accounts | H6: 👥 Customers | J6: 🚚 Vendors | L6: 👔 Employees | N6: 📦 Products | P6: 🧾 Sales
B8: 🛒 Purchases | D8: 💰 Payroll | F8: 🏦 Bank Statement | H8: ✍ General Journal | J8: 🏗 Fixed Assets | L8: 📅 Prepaid Schedule | N8: 📖 General Ledger | P8: ⚖ Trial Balance
B10: 📈 Income Statement | D10: 🏛 Balance Sheet | F10: 🔄 Changes in Equity | H10: 💧 Cash Flow | J10: 📝 Notes to FS | L10: 🧮 Tax Reconciliation | N10: 🔗 Bank Reconciliation | P10: ✅ Controls
B12: 🧾 Sales Invoice | D12: 📊 Ratios | F12: 📆 Monthly P&L | H12: 🗂 Dashboard Data
B13: ■ Setup ■ Master Data ■ Transactions ■ Schedules ■ Reports ■ Tax & Reconciliation ■ Tools
B15: SYSTEM STATUS
B16: CONTROL CHECKS | F16: TAX RECONCILIATION | J16: BANK RECONCILIATION | N16: BANK ITEMS TO BOOK
B17: =ControlStatus -> ✔ ALL CONTROLS OK | F17: ='Tax Reconciliation'!E91 -> ✔ ALL TAXES RECONCILED | J17: =IF(AND(LEFT(Controls!E21,1)="✔",LEFT(Controls!E22,1)="✔"),"✔ BCA & MANDIRI RECONCILED","✖ UNEXPLAINED DIFFERENCE") -> ✔ BCA & MANDIRI RECONCILED | N17: =Controls!E26 -> ⚠ 6 item(s) to book
B18: ="20 integrity checks – see Controls" -> 20 integrity checks – see Controls | F18: ="PPN • PPh 21 • Unifikasi • PPh 25 • PPh Badan" -> PPN • PPh 21 • Unifikasi • PPh 25 • PPh Badan | J18: ="Books vs bank statement at "&CurLabel -> Books vs bank statement at 31 October 2026 | N18: ="Interest / fees on statement not yet in GJ" -> Interest / fees on statement not yet in GJ
B20: ="FINANCIAL PERFORMANCE — YTD "&'Company Info'!C50&" "&FYear -> FINANCIAL PERFORMANCE — YTD October 2026
B21: REVENUE | F21: GROSS PROFIT | J21: NET PROFIT | N21: CASH & EQUIVALENTS
B22: =Revenue -> 11350565000 | F22: =GrossProfit -> 4518180000 | J22: =NetIncome -> 922723240 | N22: =CashBS -> 1563245568
B23: ="Avg Rp "&FIXED(Revenue/CutOff/1000000,1)&" m / month" -> Avg Rp 1.135,1 m / month | F23: ="Gross margin "&FIXED(Ratios!D13*100,1)&"%" -> Gross margin 39,8% | J23: ="Net margin "&FIXED(Ratios!D16*100,1)&"% • ROE "&FIXED(Ratios!D18*100,1)&"% (ann.)" -> Net margin 8,1% • ROE 26,6% (ann.) | N23: ="vs opening "&IF(CashBS>='Balance Sheet'!F14,"+","")&FIXED((CashBS/'Balance Sheet'!F14-1)*100,1)&"%" -> vs opening -29,7%
B25: TOTAL ASSETS | F25: CURRENT RATIO | J25: DEBT TO EQUITY | N25: CASH CONVERSION CYCLE
B26: =TotalAssets -> 7134292003 | F26: =Ratios!D9 -> 3.3235778 | J26: =Ratios!D20 -> 0.59510387 | N26: =Ratios!D28 -> 33.061539
B27: ="Equity Rp "&FIXED(TotalEquity/1000000000,2)&" bn • Liabilities Rp "&FIXED(TotalLiab/1000000000,2)&" bn" -> Equity Rp 4,47 bn • Liabilities Rp 2,66 bn | F27: =Ratios!G9&" • Quick "&FIXED(Ratios!D10,2)&"x" -> ✔ Healthy • Quick 2,41x | J27: =Ratios!G20&" • ICR "&FIXED(Ratios!D22,1)&"x" -> ✔ Healthy • ICR 10,3x | N27: ="DSO "&FIXED(Ratios!D25,0)&" • DIO "&FIXED(Ratios!D26,0)&" • DPO "&FIXED(Ratios!D27,0) -> DSO 25 • DIO 44 • DPO 36
B29: ="DAILY SNAPSHOT — "&TEXT(AnalysisDate,"[$-409]dddd, d mmmm yyyy") -> DAILY SNAPSHOT — Thursday, 8 October 2026
B30: SALES TODAY | F30: INVOICES TODAY | J30: TOP PRODUCT TODAY | N30: MONTH-TO-DATE SALES
B31: ='Dashboard Data'!C23 -> 48480000 | F31: ='Dashboard Data'!C26 -> 9 | J31: ='Dashboard Data'!C28 -> Casual Shirt | N31: ='Dashboard Data'!C30 -> 352390000
B32: =IF('Dashboard Data'!C25>=0,"▲ ","▼ ")&FIXED(ABS('Dashboard Data'!C25)*100,1)&"% vs yesterday (Rp "&FIXED('Dashboard Data'!C24/1000000,1)&" m)" -> ▲ 26,4% vs yesterday (Rp 38,3 m) | F32: ="Avg Rp "&FIXED('Dashboard Data'!C27/1000000,2)&" m / invoice • "&'Dashboard Data'!C35&" units" -> Avg Rp 5,39 m / invoice • 394 units | J32: ="Rp "&FIXED('Dashboard Data'!C29/1000000,1)&" m sold today" -> Rp 15,2 m sold today | N32: =IF('Dashboard Data'!C32>=0,"▲ ","▼ ")&FIXED(ABS('Dashboard Data'!C32)*100,1)&"% vs same period last month" -> ▲ 24,0% vs same period last month
B34: TRENDS, PRODUCTS & COST STRUCTURE
B68: TOP PRODUCTS, TODAY'S SALES BY PRODUCT, FINANCIAL HEALTH & TOP CUSTOMERS
B69: 🏆 TOP 5 PRODUCTS / SERVICES (YTD) | J69: ="📅 SALES BY PRODUCT ON "&TEXT(AnalysisDate,"[$-409]dd mmm yyyy") -> 📅 SALES BY PRODUCT ON 08 Oct 2026
B70: # | C70: Product / Service | F70: Sales | H70: Share | I70: Gross Profit | J70: Product / Service | N70: Qty | O70: Sales | Q70: Share
B71: ='Dashboard Data'!P21 -> 1 | C71: ='Dashboard Data'!Q21 -> Chino Pants | F71: ='Dashboard Data'!R21*1000000 -> 1471350000 | H71: ='Dashboard Data'!S21 -> 0.12962791 | I71: ='Dashboard Data'!T21 -> 608158000 | J71: {=INDEX(_xlfn.SORTBY('Dashboard Data'!$Q$7:$Q$16,'Dashboard Data'!$U$7:$U$16,-1),1)} -> Casual Shirt | N71: =_xlfn.XLOOKUP(J71,'Dashboard Data'!$Q$7:$Q$16,'Dashboard Data'!$V$7:$V$16,0) -> 127 | O71: =_xlfn.XLOOKUP(J71,'Dashboard Data'!$Q$7:$Q$16,'Dashboard Data'!$U$7:$U$16,0) -> 15240000 | Q71: =IFERROR(O71/'Dashboard Data'!$U$17,0) -> 0.31435644
B72: ='Dashboard Data'!P22 -> 2 | C72: ='Dashboard Data'!Q22 -> Casual Shirt | F72: ='Dashboard Data'!R22*1000000 -> 1400280000 | H72: ='Dashboard Data'!S22 -> 0.12336655 | I72: ='Dashboard Data'!T22 -> 560112000 | J72: {=INDEX(_xlfn.SORTBY('Dashboard Data'!$Q$7:$Q$16,'Dashboard Data'!$U$7:$U$16,-1),2)} -> Casual Shorts | N72: =_xlfn.XLOOKUP(J72,'Dashboard Data'!$Q$7:$Q$16,'Dashboard Data'!$V$7:$V$16,0) -> 124 | O72: =_xlfn.XLOOKUP(J72,'Dashboard Data'!$Q$7:$Q$16,'Dashboard Data'!$U$7:$U$16,0) -> 10540000 | Q72: =IFERROR(O72/'Dashboard Data'!$U$17,0) -> 0.21740924
B73: ='Dashboard Data'!P23 -> 3 | C73: ='Dashboard Data'!Q23 -> Wireless Earbuds Pro | F73: ='Dashboard Data'!R23*1000000 -> 1393750000 | H73: ='Dashboard Data'!S23 -> 0.12279124 | I73: ='Dashboard Data'!T23 -> 479450000 | J73: {=INDEX(_xlfn.SORTBY('Dashboard Data'!$Q$7:$Q$16,'Dashboard Data'!$U$7:$U$16,-1),3)} -> Sneakers | N73: =_xlfn.XLOOKUP(J73,'Dashboard Data'!$Q$7:$Q$16,'Dashboard Data'!$V$7:$V$16,0) -> 24 | O73: =_xlfn.XLOOKUP(J73,'Dashboard Data'!$Q$7:$Q$16,'Dashboard Data'!$U$7:$U$16,0) -> 6000000 | Q73: =IFERROR(O73/'Dashboard Data'!$U$17,0) -> 0.12376238
B74: ='Dashboard Data'!P24 -> 4 | C74: ='Dashboard Data'!Q24 -> Backpack | F74: ='Dashboard Data'!R24*1000000 -> 1265500000 | H74: ='Dashboard Data'!S24 -> 0.11149225 | I74: ='Dashboard Data'!T24 -> 531510000 | J74: {=INDEX(_xlfn.SORTBY('Dashboard Data'!$Q$7:$Q$16,'Dashboard Data'!$U$7:$U$16,-1),4)} -> Bomber Jacket | N74: =_xlfn.XLOOKUP(J74,'Dashboard Data'!$Q$7:$Q$16,'Dashboard Data'!$V$7:$V$16,0) -> 16 | O74: =_xlfn.XLOOKUP(J74,'Dashboard Data'!$Q$7:$Q$16,'Dashboard Data'!$U$7:$U$16,0) -> 5600000 | Q74: =IFERROR(O74/'Dashboard Data'!$U$17,0) -> 0.11551155
B75: ='Dashboard Data'!P25 -> 5 | C75: ='Dashboard Data'!Q25 -> Casual Shorts | F75: ='Dashboard Data'!R25*1000000 -> 1166030000 | H75: ='Dashboard Data'!S25 -> 0.10272881 | I75: ='Dashboard Data'!T25 -> 480130000 | J75: {=INDEX(_xlfn.SORTBY('Dashboard Data'!$Q$7:$Q$16,'Dashboard Data'!$U$7:$U$16,-1),5)} -> Premium Basic T-shirt | N75: =_xlfn.XLOOKUP(J75,'Dashboard Data'!$Q$7:$Q$16,'Dashboard Data'!$V$7:$V$16,0) -> 80 | O75: =_xlfn.XLOOKUP(J75,'Dashboard Data'!$Q$7:$Q$16,'Dashboard Data'!$U$7:$U$16,0) -> 5200000 | Q75: =IFERROR(O75/'Dashboard Data'!$U$17,0) -> 0.10726073
J76: {=INDEX(_xlfn.SORTBY('Dashboard Data'!$Q$7:$Q$16,'Dashboard Data'!$U$7:$U$16,-1),6)} -> Backpack | N76: =_xlfn.XLOOKUP(J76,'Dashboard Data'!$Q$7:$Q$16,'Dashboard Data'!$V$7:$V$16,0) -> 10 | O76: =_xlfn.XLOOKUP(J76,'Dashboard Data'!$Q$7:$Q$16,'Dashboard Data'!$U$7:$U$16,0) -> 5000000 | Q76: =IFERROR(O76/'Dashboard Data'!$U$17,0) -> 0.10313531
B77: 🩺 FINANCIAL HEALTH | J77: {=INDEX(_xlfn.SORTBY('Dashboard Data'!$Q$7:$Q$16,'Dashboard Data'!$U$7:$U$16,-1),7)} -> Socks & Accessories | N77: =_xlfn.XLOOKUP(J77,'Dashboard Data'!$Q$7:$Q$16,'Dashboard Data'!$V$7:$V$16,0) -> 10 | O77: =_xlfn.XLOOKUP(J77,'Dashboard Data'!$Q$7:$Q$16,'Dashboard Data'!$U$7:$U$16,0) -> 450000 | Q77: =IFERROR(O77/'Dashboard Data'!$U$17,0) -> 0.0092821782
B78: Ratio | F78: Value | H78: Status | J78: {=INDEX(_xlfn.SORTBY('Dashboard Data'!$Q$7:$Q$16,'Dashboard Data'!$U$7:$U$16,-1),8)} -> Chino Pants | N78: =_xlfn.XLOOKUP(J78,'Dashboard Data'!$Q$7:$Q$16,'Dashboard Data'!$V$7:$V$16,0) -> 3 | O78: =_xlfn.XLOOKUP(J78,'Dashboard Data'!$Q$7:$Q$16,'Dashboard Data'!$U$7:$U$16,0) -> 450000 | Q78: =IFERROR(O78/'Dashboard Data'!$U$17,0) -> 0.0092821782
B79: Current ratio | F79: =Ratios!D9 -> 3.3235778 | H79: =Ratios!G9 -> ✔ Healthy | J79: {=INDEX(_xlfn.SORTBY('Dashboard Data'!$Q$7:$Q$16,'Dashboard Data'!$U$7:$U$16,-1),9)} -> Smartwatch | N79: =_xlfn.XLOOKUP(J79,'Dashboard Data'!$Q$7:$Q$16,'Dashboard Data'!$V$7:$V$16,0) -> 0 | O79: =_xlfn.XLOOKUP(J79,'Dashboard Data'!$Q$7:$Q$16,'Dashboard Data'!$U$7:$U$16,0) -> 0 | Q79: =IFERROR(O79/'Dashboard Data'!$U$17,0) -> 0
B80: Quick ratio | F80: =Ratios!D10 -> 2.4115836 | H80: =Ratios!G10 -> ✔ Healthy | J80: {=INDEX(_xlfn.SORTBY('Dashboard Data'!$Q$7:$Q$16,'Dashboard Data'!$U$7:$U$16,-1),10)} -> Wireless Earbuds Pro | N80: =_xlfn.XLOOKUP(J80,'Dashboard Data'!$Q$7:$Q$16,'Dashboard Data'!$V$7:$V$16,0) -> 0 | O80: =_xlfn.XLOOKUP(J80,'Dashboard Data'!$Q$7:$Q$16,'Dashboard Data'!$U$7:$U$16,0) -> 0 | Q80: =IFERROR(O80/'Dashboard Data'!$U$17,0) -> 0
B81: Net profit margin | F81: =Ratios!D16 -> 0.081293155 | H81: =Ratios!G16 -> ✔ Healthy | J81: Total today | N81: ='Dashboard Data'!V17 -> 394 | O81: ='Dashboard Data'!U17 -> 48480000
B82: Return on assets (ann.) | F82: =Ratios!D17 -> 0.15911664 | H82: =Ratios!G17 -> ✔ Healthy
B83: Return on equity (ann.) | F83: =Ratios!D18 -> 0.26608973 | H83: =Ratios!G18 -> ✔ Healthy | J83: 🤝 TOP 5 CUSTOMERS (YTD, excl. walk-in)
...

Sheet Company Info
B2: 🏠 HOME | D2: ◀ PREV | F2: NEXT ▶ | I2: ☰ MENU | L2: Journal | O2: Trial Bal. | R2: Income St. | U2: Balance Sh. | X2: Tax Recon | AA2: Bank Recon | AD2: Controls
B4: COMPANY INFORMATION & SETTINGS
B5: IDENTITY
B6: Company Name | C6: PT Nusantara Sejahtera Abadi | D6: Appears on all reports
B7: Business Type | C7: Retail | D7: ▼ Select industry
B8: Business Description | C8: =IP_Desc -> Retail of fashion, lifestyle & consumer electronics | D8: Auto from Industry Profile
B9: Tax ID (NPWP) | C9: 0123456789012000 | D9: 16-digit NPWP
B10: Business ID (NIB) | C10: 9120001234567
B11: VAT Status | C11: PKP (VAT-registered)
B12: Address | C12: Jl. Jend. Sudirman Kav. 52-53, Jakarta Selatan 12190
B13: City | C13: Jakarta
B14: Phone | C14: +62 21 5150 8888
B15: Email | C15: finance@nusantarasejahtera.co.id
B16: Date of Establishment | C16: 43174
B17: Deed of Establishment | C17: Deed No. 12 dated 15 March 2018, Notary Andi Wijaya, S.H., M.Kn.
B18: Ministry Approval | C18: AHU-0012345.AH.01.01.Tahun 2018
B19: Number of Employees | C19: =ROWS(tblEmployees[Employee ID]) -> 15 | D19: Auto from Employees
B20: Shares Outstanding | C20: 2500000 | D20: shares
B21: Par Value per Share (IDR) | C21: 1000
B22: MANAGEMENT
B23: President Commissioner | C23: Hendra Gunawan
B24: President Director | C24: Budi Santoso
B25: Finance Director | C25: Siti Rahmawati
B26: Accounting Manager | C26: Dewi Lestari
B28: REPORTING PERIOD
B29: Fiscal Year | C29: 2026
B30: Cut-off Month (1-12) | C30: 10 | D30: ▼ All reports run YTD to this month
B31: Period Start | C31: =DATE(C29,1,1) -> 46023
B32: Period End | C32: =EOMONTH(DATE(C29,C30,1),0) -> 46326 | D32: Auto
B33: Comparative Date | C33: =DATE(C29-1,12,31) -> 46022 | D33: Opening balances date
B34: Reporting Currency | C34: Indonesian Rupiah (IDR)
B35: Presentation Unit | C35: Full Rupiah
B36: TAX SETTINGS
B37: VAT Rate (PPN) | C37: 0.12 | D37: UU HPP; from 1 Jan 2025
B38: VAT Base Factor (DPP Nilai Lain) | C38: =11/12 -> 0.91666667 | D38: PMK 131/2024 – non-luxury goods
B39: Effective VAT Rate | C39: =C37*C38 -> 0.11
B40: Corporate Income Tax Rate | C40: 0.22 | D40: Art. 17 UU PPh
B41: Apply Art. 31E Facility (Yes/No) | C41: Yes | D41: ▼ 50% rate cut on revenue ≤ IDR 4.8bn portion
B42: Art. 31E Revenue Threshold | C42: 4800000000
B43: Monthly PPh 25 Installment | C43: 20000000 | D43: Per prior-year SPT
...

Sheet Industry Profile
B2: 🏠 HOME | D2: ◀ PREV | F2: NEXT ▶ | H2: ☰ MENU | J2: Journal | L2: Trial Bal. | O2: Income St. | R2: Balance Sh. | U2: Tax Recon | X2: Bank Recon | AA2: Controls
B4: INDUSTRY PROFILE LIBRARY
B5: Edit any industry column (blue) to customise labels/products. Column C is driven by Company Info › Business Type.
B6: Attribute | C6: ▶ Selected | D6: Retail | E6: Services | F6: Manufacturing | G6: Distribution | H6: Construction | I6: Trading Company | J6: Fulfillment | K6: F&B
B7: Description | C7: =INDEX(D7:K7,MATCH(Industry,$D$6:$K$6,0)) -> Retail of fashion, lifestyle & consumer electronics | D7: Retail of fashion, lifestyle & consumer electronics | E7: Business consulting, creative & digital services | F7: Manufacturing of furniture & home products | G7: Wholesale distribution of fast-moving consumer goods | H7: Building construction & finishing contractor | I7: B2B trading of industrial supplies & equipment | J7: E-commerce fulfillment & warehousing services | K7: Restaurant, café & catering services
B8: Revenue Label | C8: =INDEX(D8:K8,MATCH(Industry,$D$6:$K$6,0)) -> Sales of goods | D8: Sales of goods | E8: Service revenue | F8: Sales of manufactured goods | G8: Sales of goods - distribution | H8: Contract revenue | I8: Trading revenue | J8: Fulfillment service revenue | K8: Food & beverage sales
B9: Cost of Revenue Label | C9: =INDEX(D9:K9,MATCH(Industry,$D$6:$K$6,0)) -> Cost of goods sold | D9: Cost of goods sold | E9: Cost of services | F9: Cost of goods manufactured & sold | G9: Cost of goods sold | H9: Contract costs | I9: Cost of goods sold | J9: Cost of services | K9: Cost of food & beverage
B10: Inventory Label | C10: =INDEX(D10:K10,MATCH(Industry,$D$6:$K$6,0)) -> Merchandise inventory | D10: Merchandise inventory | E10: Service supplies | F10: Finished goods & raw materials | G10: Merchandise inventory | H10: Construction materials | I10: Trading inventory | J10: Packaging & supplies | K10: Food & beverage inventory
B11: Unit | C11: =INDEX(D11:K11,MATCH(Industry,$D$6:$K$6,0)) -> pcs | D11: pcs | E11: session | F11: unit | G11: carton | H11: m² / m³ | I11: unit | J11: order batch | K11: portion
B12: Category 1 | C12: =INDEX(D12:K12,MATCH(Industry,$D$6:$K$6,0)) -> Accessories & Basics | D12: Accessories & Basics | E12: Digital Content | F12: Small Furniture | G12: Beverages | H12: Finishing Works | I12: Packaging Supplies | J12: Handling Services | K12: Beverages & Snacks
B13: Category 2 | C13: =INDEX(D13:K13,MATCH(Industry,$D$6:$K$6,0)) -> Apparel & Footwear | D13: Apparel & Footwear | E13: Consulting | F13: Chairs & Tables | G13: Food Staples | H13: Structural Works | I13: Industrial Parts | J13: Storage Services | K13: Main Courses
B14: Category 3 | C14: =INDEX(D14:K14,MATCH(Industry,$D$6:$K$6,0)) -> Bags & Gadgets | D14: Bags & Gadgets | E14: Projects & Retainers | F14: Large Furniture | G14: Household Goods | H14: Concrete & Heavy Works | I14: Machinery & Tools | J14: Value-added Services | K14: Packages & Catering
B15: Channel 1 | C15: =INDEX(D15:K15,MATCH(Industry,$D$6:$K$6,0)) -> In-store | D15: In-store | E15: Direct Client | F15: Distributor | G15: Modern Trade | H15: Private Projects | I15: Direct Sales | J15: Marketplace Sellers | K15: Dine-in
B16: Channel 2 | C16: =INDEX(D16:K16,MATCH(Industry,$D$6:$K$6,0)) -> Marketplace | D16: Marketplace | E16: Referral | F16: Direct B2B | G16: General Trade | H16: Government Projects | I16: Tender | J16: D2C Brands | K16: Delivery App
B17: Channel 3 | C17: =INDEX(D17:K17,MATCH(Industry,$D$6:$K$6,0)) -> Website & Social Media | D17: Website & Social Media | E17: Online Platform | F17: E-commerce | G17: B2B Online | H17: Subcontract | I17: E-procurement | J17: Corporate | K17: Catering Order
B18: Product P01 | C18: =INDEX(D18:K18,MATCH(Industry,$D$6:$K$6,0)) -> Socks & Accessories | D18: Socks & Accessories | E18: Online Consultation (30 min) | F18: Plastic Stool | G18: Mineral Water 600ml (carton) | H18: Painting Works (m²) | I18: Packing Tape (pack) | J18: Pick & Pack (10 orders) | K18: Iced Palm Sugar Coffee
... B28: Revenue Recognition Policy | C28: =INDEX(D28:K28,MATCH(Industry,$D$6:$K$6,0)) -> Revenue from the sale of goods is recognised at a point in time when control transfers to the customer, generally upon handover at the store or delivery to the courier (PSAK 115). | D28: Revenue from the sale of goods is recognised at a point in time when control transfers to the customer, generally upon handover at the store or delivery to the courier (PSAK 115). | E28: Service revenue is recognised over time as the services are rendered, or at a point in time when a discrete session/deliverable is completed (PSAK 115). | F28: Revenue is recognised at a point in time when manufactured goods are delivered and accepted by the customer (PSAK 115). | G28: Revenue is recognised when goods are delivered to the customer's warehouse and control has transferred (PSAK 115). | H28: Contract revenue is recognised over time using the input method, based on costs incurred relative to total estimated contract costs (PSAK 115). | I28: Revenue is recognised at a point in time when control passes to the buyer in accordance with the agreed delivery terms (PSAK 115). | J28: Fulfillment and storage revenue is recognised over time as the services are performed (PSAK 115). | K28: Revenue is recognised at a point in time when food and beverages are served or delivered to the customer (PSAK 115).

Sheet COA
B2: 🏠 HOME | E2: ◀ PREV | G2: NEXT ▶ | J2: ☰ MENU | M2: Journal | P2: Trial Bal. | S2: Income St. | V2: Balance Sh. | Y2: Tax Recon | AB2: Bank Recon | AE2: Controls
B4: CHART OF ACCOUNTS & OPENING BALANCES
B5: Opening balances as at Comparative Date. Black = linked to schedules (FA / Prepaid). Add new accounts at the bottom; FS Line & CF Line control where they appear.
B6: Code | C6: Account Name | D6: Class | E6: FS Line | F6: Normal | G6: Note | H6: CF Line | I6: Opening Balance | K6: OPENING BALANCE CHECK | L6: Amount
B7: 1110 | C7: Cash on Hand | D7: Asset | E7: Cash and cash equivalents | F7: D | G7: 3 | H7: Cash | I7: 25000000 | K7: Total debit-normal balances | L7: =SUMIFS(tblCOA[Opening Balance],tblCOA[Normal],"D") -> 8742000000
B8: 1120 | C8: Bank BCA - Current Account | D8: Asset | E8: Cash and cash equivalents | F8: D | G8: 3 | H8: Cash | I8: 1250000000 | K8: Total credit-normal balances | L8: =SUMIFS(tblCOA[Opening Balance],tblCOA[Normal],"C") -> 8742000000
B9: 1130 | C9: Bank Mandiri - Current Account | D9: Asset | E9: Cash and cash equivalents | F9: D | G9: 3 | H9: Cash | I9: 450000000 | K9: Difference (must be 0) | L9: =L7-L8 -> 0
B10: 1140 | C10: Time Deposit (≤ 3 months) | D10: Asset | E10: Cash and cash equivalents | F10: D | G10: 3 | H10: Cash | I10: 500000000 | K10: Status | L10: =IF(ABS(L9)<1,"✔ Balanced","✖ Not balanced") -> ✔ Balanced
B11: 1210 | C11: Trade Receivables | D11: Asset | E11: Trade receivables - net | F11: D | G11: 4 | H11: Receivables | I11: 420000000 | K11: Accounts in COA | L11: =ROWS(tblCOA[Code]) -> 68
B12: 1220 | C12: Allowance for Expected Credit Losses | D12: Asset | E12: Trade receivables - net | F12: C | G12: 4 | H12: Receivables | I12: 20000000
B13: 1230 | C13: Other Receivables | D13: Asset | E13: Other receivables | F13: D | G13: 4 | H13: Receivables | I13: 25000000
B14: 1310 | C14: =IP_InvLabel -> Merchandise inventory | D14: Asset | E14: Inventories | F14: D | G14: 5 | H14: Inventories | I14: 950000000
B15: 1410 | C15: Prepaid Rent | D15: Asset | E15: Prepaid expenses | F15: D | G15: 6 | H15: Prepaid expenses | I15: =SUMIFS(tblPrepaid[Opening Balance],tblPrepaid[Prepaid Account],tblCOA[[#This Row],[Code]]) -> 132000000
B16: 1420 | C16: Prepaid Insurance | D16: Asset | E16: Prepaid expenses | F16: D | G16: 6 | H16: Prepaid expenses | I16: =SUMIFS(tblPrepaid[Opening Balance],tblPrepaid[Prepaid Account],tblCOA[[#This Row],[Code]]) -> 25000000
B17: 1430 | C17: Prepaid Software Subscriptions | D17: Asset | E17: Prepaid expenses | F17: D | G17: 6 | H17: Prepaid expenses | I17: =SUMIFS(tblPrepaid[Opening Balance],tblPrepaid[Prepaid Account],tblCOA[[#This Row],[Code]]) -> 15000000
B18: 1510 | C18: Input VAT (PPN Masukan) | D18: Asset | E18: Prepaid taxes | F18: D | G18: 7 | H18: Prepaid taxes | I18: 0
B19: 1520 | C19: Prepaid Income Tax - Art. 25 | D19: Asset | E19: Prepaid taxes | F19: D | G19: 7 | H19: Prepaid taxes | I19: 0
B20: 1610 | C20: Land | D20: Asset | E20: Fixed assets - net | F20: D | G20: 8 | H20: Fixed assets | I20: =SUMIFS(tblFA[Cost],tblFA[Cost Account],tblCOA[[#This Row],[Code]],tblFA[Acquisition Date],"<="&CompDate) -> 1200000000
B21: 1620 | C21: Buildings | D21: Asset | E21: Fixed assets - net | F21: D | G21: 8 | H21: Fixed assets | I21: =SUMIFS(tblFA[Cost],tblFA[Cost Account],tblCOA[[#This Row],[Code]],tblFA[Acquisition Date],"<="&CompDate) -> 1800000000
B22: 1630 | C22: Vehicles | D22: Asset | E22: Fixed assets - net | F22: D | G22: 8 | H22: Fixed assets | I22: =SUMIFS(tblFA[Cost],tblFA[Cost Account],tblCOA[[#This Row],[Code]],tblFA[Acquisition Date],"<="&CompDate) -> 700000000
B23: 1640 | C23: Machinery & Equipment | D23: Asset | E23: Fixed assets - net | F23: D | G23: 8 | H23: Fixed assets | I23: =SUMIFS(tblFA[Cost],tblFA[Cost Account],tblCOA[[#This Row],[Code]],tblFA[Acquisition Date],"<="&CompDate) -> 800000000
B24: 1650 | C24: Office Furniture & Equipment | D24: Asset | E24: Fixed assets - net | F24: D | G24: 8 | H24: Fixed assets | I24: =SUMIFS(tblFA[Cost],tblFA[Cost Account],tblCOA[[#This Row],[Code]],tblFA[Acquisition Date],"<="&CompDate) -> 270000000
B25: 1691 | C25: Acc. Depreciation - Buildings | D25: Asset | E25: Fixed assets - net | F25: C | G25: 8 | H25: Depreciation & amortization | I25: =SUMIFS(tblFA[Opening Acc. Dep.],tblFA[Acc. Dep. Account],tblCOA[[#This Row],[Code]]) -> 697500000
B26: 1693 | C26: Acc. Depreciation - Vehicles | D26: Asset | E26: Fixed assets - net | F26: C | G26: 8 | H26: Depreciation & amortization | I26: =SUMIFS(tblFA[Opening Acc. Dep.],tblFA[Acc. Dep. Account],tblCOA[[#This Row],[Code]]) -> 377708349
B27: 1694 | C27: Acc. Depreciation - Machinery & Equipment | D27: Asset | E27: Fixed assets - net | F27: C | G27: 8 | H27: Depreciation & amortization | I27: =SUMIFS(tblFA[Opening Acc. Dep.],tblFA[Acc. Dep. Account],tblCOA[[#This Row],[Code]]) -> 523645817
B28: 1695 | C28: Acc. Depreciation - Office Furniture & Equipment | D28: Asset | E28: Fixed assets - net | F28: C | G28: 8 | H28: Depreciation & amortization | I28: =SUMIFS(tblFA[Opening Acc. Dep.],tblFA[Acc. Dep. Account],tblCOA[[#This Row],[Code]]) -> 204750000
B29: 1710 | C29: Software & Licenses | D29: Asset | E29: Intangible assets - net | F29: D | G29: 9 | H29: Intangible assets | I29: =SUMIFS(tblFA[Cost],tblFA[Cost Account],tblCOA[[#This Row],[Code]],tblFA[Acquisition Date],"<="&CompDate) -> 180000000
B30: 1719 | C30: Acc. Amortization - Software | D30: Asset | E30: Intangible assets - net | F30: C | G30: 9 | H30: Depreciation & amortization | I30: =SUMIFS(tblFA[Opening Acc. Dep.],tblFA[Acc. Dep. Account],tblCOA[[#This Row],[Code]]) -> 135000000
B31: 2110 | C31: Trade Payables | D31: Liability | E31: Trade payables | F31: C | G31: 10 | H31: Trade payables | I31: 620000000
B32: 2120 | C32: Other Payables | D32: Liability | E32: Other payables | F32: C | G32: 11 | H32: Other liabilities | I32: 35000000
B33: 2130 | C33: Accrued Expenses | D33: Liability | E33: Accrued expenses | F33: C | G33: 11 | H33: Other liabilities | I33: 45000000
B34: 2140 | C34: Contract Liabilities | D34: Liability | E34: Contract liabilities | F34: C | G34: 11 | H34: Other liabilities | I34: 40000000
B35: 2150 | C35: BPJS Payable | D35: Liability | E35: Accrued expenses | F35: C | G35: 11 | H35: Other liabilities | I35: 18000000
B36: 2210 | C36: Output VAT (PPN Keluaran) | D36: Liability | E36: Taxes payable | F36: C | G36: 7 | H36: Taxes payable | I36: 0
B37: 2220 | C37: VAT Payable - Net | D37: Liability | E37: Taxes payable | F37: C | G37: 7 | H37: Taxes payable | I37: 85000000
B38: 2230 | C38: WHT Payable - Art. 21 | D38: Liability | E38: Taxes payable | F38: C | G38: 7 | H38: Taxes payable | I38: 14000000
B39: 2240 | C39: WHT Payable - Unifikasi (Art. 23/4(2)) | D39: Liability | E39: Taxes payable | F39: C | G39: 7 | H39: Taxes payable | I39: 6500000
B40: 2250 | C40: Corporate Income Tax Payable (Art. 29) | D40: Liability | E40: Taxes payable | F40: C | G40: 7 | H40: Taxes payable | I40: 60000000
B41: 2310 | C41: Short-term Bank Loan | D41: Liability | E41: Short-term bank loans | F41: C | G41: 12 | H41: Bank loans | I41: 300000000
B42: 2410 | C42: Long-term Bank Loan | D42: Liability | E42: Long-term bank loans | F42: C | G42: 12 | H42: Bank loans | I42: 1500000000
...

Sheet Customers
B2: 🏠 HOME | E2: ◀ PREV | G2: NEXT ▶ | I2: ☰ MENU | K2: Journal | M2: Trial Bal. | P2: Income St. | S2: Balance Sh. | V2: Tax Recon | Y2: Bank Recon | AB2: Controls
B4: CUSTOMER MASTER
B5: Add new customers at the bottom of the table. Customer ID is used in Sales & Sales Invoice.
B6: Customer ID | C6: Customer Name | D6: Type | E6: NPWP | F6: Address | G6: City | H6: Email | I6: Phone | J6: Payment Terms (days) | K6: Credit Limit | L6: Sales YTD (DPP) | M6: Outstanding AR (est.)
B7: C000 | C7: Walk-in Customer | D7: Retail | E7: 0000000000000000 | F7: - | G7: Jakarta | H7: - | I7: - | J7: 0 | K7: 0 | L7: =SUMIFS(tblSales[DPP (excl. VAT)],tblSales[Customer ID],tblCustomers[[#This Row],[Customer ID]],tblSales[Date],"<="&PEnd) -> 3191885000 | M7: =SUMIFS(tblSales[Total incl. VAT],tblSales[Customer ID],tblCustomers[[#This Row],[Customer ID]],tblSales[Payment Method],"Credit (Term)",tblSales[Month],CutOff) -> 0
B8: C001 | C8: PT Cahaya Abadi Makmur | D8: Corporate | E8: 0213456789012000 | F8: Jl. Gatot Subroto No. 21 | G8: Jakarta | H8: ap@cahayaabadi.co.id | I8: 021-5201188 | J8: 30 | K8: 250000000 | L8: =SUMIFS(tblSales[DPP (excl. VAT)],tblSales[Customer ID],tblCustomers[[#This Row],[Customer ID]],tblSales[Date],"<="&PEnd) -> 827360000 | M8: =SUMIFS(tblSales[Total incl. VAT],tblSales[Customer ID],tblCustomers[[#This Row],[Customer ID]],tblSales[Payment Method],"Credit (Term)",tblSales[Month],CutOff) -> 117615600
B9: C002 | C9: PT Bintang Timur Sejahtera | D9: Corporate | E9: 0314567890123000 | F9: Jl. Ahmad Yani No. 88 | G9: Surabaya | H9: finance@bintangtimur.co.id | I9: 031-5678120 | J9: 30 | K9: 200000000 | L9: =SUMIFS(tblSales[DPP (excl. VAT)],tblSales[Customer ID],tblCustomers[[#This Row],[Customer ID]],tblSales[Date],"<="&PEnd) -> 844240000 | M9: =SUMIFS(tblSales[Total incl. VAT],tblSales[Customer ID],tblCustomers[[#This Row],[Customer ID]],tblSales[Payment Method],"Credit (Term)",tblSales[Month],CutOff) -> 192340800
B10: C003 | C10: CV Mitra Karya Mandiri | D10: SME | E10: 0415678901234000 | F10: Jl. Asia Afrika No. 102 | G10: Bandung | H10: mitrakarya@gmail.com | I10: 022-4231987 | J10: 14 | K10: 100000000 | L10: =SUMIFS(tblSales[DPP (excl. VAT)],tblSales[Customer ID],tblCustomers[[#This Row],[Customer ID]],tblSales[Date],"<="&PEnd) -> 512560000 | M10: =SUMIFS(tblSales[Total incl. VAT],tblSales[Customer ID],tblCustomers[[#This Row],[Customer ID]],tblSales[Payment Method],"Credit (Term)",tblSales[Month],CutOff) -> 97014000
B11: C004 | C11: PT Graha Nusa Persada | D11: Corporate | E11: 0516789012345000 | F11: Jl. HR Rasuna Said Kav. 5 | G11: Jakarta | H11: ap@grahanusa.co.id | I11: 021-5290044 | J11: 30 | K11: 300000000 | L11: =SUMIFS(tblSales[DPP (excl. VAT)],tblSales[Customer ID],tblCustomers[[#This Row],[Customer ID]],tblSales[Date],"<="&PEnd) -> 927360000 | M11: =SUMIFS(tblSales[Total incl. VAT],tblSales[Customer ID],tblCustomers[[#This Row],[Customer ID]],tblSales[Payment Method],"Credit (Term)",tblSales[Month],CutOff) -> 91108800
B12: C005 | C12: PT Samudra Jaya Logistik | D12: Corporate | E12: 0617890123456000 | F12: Jl. Yos Sudarso No. 17 | G12: Jakarta Utara | H12: finance@samudrajaya.co.id | I12: 021-4301255 | J12: 45 | K12: 250000000 | L12: =SUMIFS(tblSales[DPP (excl. VAT)],tblSales[Customer ID],tblCustomers[[#This Row],[Customer ID]],tblSales[Date],"<="&PEnd) -> 712240000 | M12: =SUMIFS(tblSales[Total incl. VAT],tblSales[Customer ID],tblCustomers[[#This Row],[Customer ID]],tblSales[Payment Method],"Credit (Term)",tblSales[Month],CutOff) -> 82006800
B13: C006 | C13: PT Arunika Digital Kreatif | D13: Corporate | E13: 0718901234567000 | F13: Jl. Kemang Raya No. 9 | G13: Jakarta Selatan | H13: billing@arunika.id | I13: 021-7190033 | J13: 30 | K13: 150000000 | L13: =SUMIFS(tblSales[DPP (excl. VAT)],tblSales[Customer ID],tblCustomers[[#This Row],[Customer ID]],tblSales[Date],"<="&PEnd) -> 443600000 | M13: =SUMIFS(tblSales[Total incl. VAT],tblSales[Customer ID],tblCustomers[[#This Row],[Customer ID]],tblSales[Payment Method],"Credit (Term)",tblSales[Month],CutOff) -> 68464800
B14: C007 | C14: PT Mega Prima Distribusi | D14: Corporate | E14: 0819012345678000 | F14: Jl. Raya Bekasi Km 22 | G14: Bekasi | H14: ap@megaprima.co.id | I14: 021-8834567 | J14: 30 | K14: 300000000 | L14: =SUMIFS(tblSales[DPP (excl. VAT)],tblSales[Customer ID],tblCustomers[[#This Row],[Customer ID]],tblSales[Date],"<="&PEnd) -> 776080000 | M14: =SUMIFS(tblSales[Total incl. VAT],tblSales[Customer ID],tblCustomers[[#This Row],[Customer ID]],tblSales[Payment Method],"Credit (Term)",tblSales[Month],CutOff) -> 65978400
B15: C008 | C15: CV Sumber Rejeki Utama | D15: SME | E15: 0910123456789000 | F15: Jl. Pemuda No. 45 | G15: Semarang | H15: sumberrejeki@yahoo.com | I15: 024-3567812 | J15: 14 | K15: 80000000 | L15: =SUMIFS(tblSales[DPP (excl. VAT)],tblSales[Customer ID],tblCustomers[[#This Row],[Customer ID]],tblSales[Date],"<="&PEnd) -> 456720000 | M15: =SUMIFS(tblSales[Total incl. VAT],tblSales[Customer ID],tblCustomers[[#This Row],[Customer ID]],tblSales[Payment Method],"Credit (Term)",tblSales[Month],CutOff) -> 72416400
B16: C009 | C16: PT Kencana Wira Usaha | D16: Corporate | E16: 1011234567890000 | F16: Jl. Diponegoro No. 61 | G16: Medan | H16: finance@kencanawira.co.id | I16: 061-4155223 | J16: 30 | K16: 200000000 | L16: =SUMIFS(tblSales[DPP (excl. VAT)],tblSales[Customer ID],tblCustomers[[#This Row],[Customer ID]],tblSales[Date],"<="&PEnd) -> 768960000 | M16: =SUMIFS(tblSales[Total incl. VAT],tblSales[Customer ID],tblCustomers[[#This Row],[Customer ID]],tblSales[Payment Method],"Credit (Term)",tblSales[Month],CutOff) -> 33344400
B17: C010 | C17: PT Delta Inti Selaras | D17: Corporate | E17: 1112345678901000 | F17: Jl. Sudirman No. 120 | G17: Pekanbaru | H17: ap@deltainti.co.id | I17: 0761-855421 | J17: 30 | K17: 150000000 | L17: =SUMIFS(tblSales[DPP (excl. VAT)],tblSales[Customer ID],tblCustomers[[#This Row],[Customer ID]],tblSales[Date],"<="&PEnd) -> 821240000 | M17: =SUMIFS(tblSales[Total incl. VAT],tblSales[Customer ID],tblCustomers[[#This Row],[Customer ID]],tblSales[Payment Method],"Credit (Term)",tblSales[Month],CutOff) -> 122277600
B18: C011 | C18: PT Harmoni Pangan Lestari | D18: Corporate | E18: 1213456789012000 | F18: Jl. Raya Kuta No. 77 | G18: Badung, Bali | H18: finance@harmonipangan.co.id | I18: 0361-756210 | J18: 30 | K18: 200000000 | L18: =SUMIFS(tblSales[DPP (excl. VAT)],tblSales[Customer ID],tblCustomers[[#This Row],[Customer ID]],tblSales[Date],"<="&PEnd) -> 491440000 | M18: =SUMIFS(tblSales[Total incl. VAT],tblSales[Customer ID],tblCustomers[[#This Row],[Customer ID]],tblSales[Payment Method],"Credit (Term)",tblSales[Month],CutOff) -> 33655200
B19: C012 | C19: PT Lintas Benua Niaga | D19: Corporate | E19: 1314567890123000 | F19: Jl. MH Thamrin No. 3 | G19: Jakarta Pusat | H19: ap@lintasbenua.co.id | I19: 021-3900812 | J19: 45 | K19: 350000000 | L19: =SUMIFS(tblSales[DPP (excl. VAT)],tblSales[Customer ID],tblCustomers[[#This Row],[Customer ID]],tblSales[Date],"<="&PEnd) -> 576880000 | M19: =SUMIFS(tblSales[Total incl. VAT],tblSales[Customer ID],tblCustomers[[#This Row],[Customer ID]],tblSales[Payment Method],"Credit (Term)",tblSales[Month],CutOff) -> 81118800

Sheet Vendors
B2: 🏠 HOME | E2: ◀ PREV | G2: NEXT ▶ | I2: ☰ MENU | K2: Journal | M2: Trial Bal. | O2: Income St. | R2: Balance Sh. | U2: Tax Recon | X2: Bank Recon | AA2: Controls
B4: VENDOR MASTER
B5: VAT Status drives Input VAT; WHT Type drives PPh Unifikasi withholding on Purchases.
B6: Vendor ID | C6: Vendor Name | D6: Category | E6: NPWP | F6: VAT Status | G6: WHT Type | H6: Default Account | I6: Address | J6: Bank Account | K6: Payment Terms (days) | L6: Purchases YTD (DPP) | M6: Unpaid at Period End
B7: V001 | C7: PT Sumber Barang Utama | D7: Inventory Supplier | E7: 0123987654321000 | F7: PKP | G7: None | H7: 1310 | I7: Jl. Industri Raya No. 8, Tangerang | J7: BCA 5270011122 | K7: 30 | L7: =SUMIFS(tblPurchases[DPP (excl. VAT)],tblPurchases[Vendor ID],tblVendors[[#This Row],[Vendor ID]],tblPurchases[Date],"<="&PEnd) -> 3431971000 | M7: =SUMIFS(tblPurchases[Total Payable],tblPurchases[Vendor ID],tblVendors[[#This Row],[Vendor ID]],tblPurchases[Date],"<="&PEnd,tblPurchases[Payment Date],">"&PEnd) -> 431996460
B8: V002 | C8: PT Prima Supply Nusantara | D8: Inventory Supplier | E8: 0234987654321000 | F8: PKP | G8: None | H8: 1310 | I8: Kawasan Pulogadung Blok C2, Jakarta | J8: Mandiri 1230004455 | K8: 30 | L8: =SUMIFS(tblPurchases[DPP (excl. VAT)],tblPurchases[Vendor ID],tblVendors[[#This Row],[Vendor ID]],tblPurchases[Date],"<="&PEnd) -> 2402381000 | M8: =SUMIFS(tblPurchases[Total Payable],tblPurchases[Vendor ID],tblVendors[[#This Row],[Vendor ID]],tblPurchases[Date],"<="&PEnd,tblPurchases[Payment Date],">"&PEnd) -> 302397300
B9: V003 | C9: CV Aneka Grosir Jaya | D9: Inventory Supplier | E9: 0345987654321000 | F9: Non-PKP | G9: None | H9: 1310 | I9: Pasar Tanah Abang Blok A, Jakarta | J9: BRI 0342010099 | K9: 7 | L9: =SUMIFS(tblPurchases[DPP (excl. VAT)],tblPurchases[Vendor ID],tblVendors[[#This Row],[Vendor ID]],tblPurchases[Date],"<="&PEnd) -> 1029592000 | M9: =SUMIFS(tblPurchases[Total Payable],tblPurchases[Vendor ID],tblVendors[[#This Row],[Vendor ID]],tblPurchases[Date],"<="&PEnd,tblPurchases[Payment Date],">"&PEnd) -> 0
B10: V004 | C10: PT Graha Properti Sudirman | D10: Building Rent | E10: 0456987654321000 | F10: PKP | G10: Art. 4(2) - Building Rent | H10: 1410 | I10: Jl. Jend. Sudirman Kav. 52, Jakarta | J10: BNI 0098812233 | K10: 0 | L10: =SUMIFS(tblPurchases[DPP (excl. VAT)],tblPurchases[Vendor ID],tblVendors[[#This Row],[Vendor ID]],tblPurchases[Date],"<="&PEnd) -> 0 | M10: =SUMIFS(tblPurchases[Total Payable],tblPurchases[Vendor ID],tblVendors[[#This Row],[Vendor ID]],tblPurchases[Date],"<="&PEnd,tblPurchases[Payment Date],">"&PEnd) -> 0
B11: V005 | C11: PT Asuransi Proteksi Indonesia | D11: Insurance | E11: 0567987654321000 | F11: VAT-exempt | G11: None | H11: 1420 | I11: Jl. Thamrin No. 15, Jakarta | J11: BCA 6040987654 | K11: 14 | L11: =SUMIFS(tblPurchases[DPP (excl. VAT)],tblPurchases[Vendor ID],tblVendors[[#This Row],[Vendor ID]],tblPurchases[Date],"<="&PEnd) -> 36000000 | M11: =SUMIFS(tblPurchases[Total Payable],tblPurchases[Vendor ID],tblVendors[[#This Row],[Vendor ID]],tblPurchases[Date],"<="&PEnd,tblPurchases[Payment Date],">"&PEnd) -> 36000000
B12: V006 | C12: PT Cloud Software Indonesia | D12: Software Subscription | E12: 0678987654321000 | F12: PKP | G12: Art. 23 - Services | H12: 1430 | I12: Jl. TB Simatupang No. 18, Jakarta | J12: BCA 8830556677 | K12: 7 | L12: =SUMIFS(tblPurchases[DPP (excl. VAT)],tblPurchases[Vendor ID],tblVendors[[#This Row],[Vendor ID]],tblPurchases[Date],"<="&PEnd) -> 72000000 | M12: =SUMIFS(tblPurchases[Total Payable],tblPurchases[Vendor ID],tblVendors[[#This Row],[Vendor ID]],tblPurchases[Date],"<="&PEnd,tblPurchases[Payment Date],">"&PEnd) -> 0
B13: V007 | C13: PT Kreasi Iklan Digital | D13: Advertising Agency | E13: 0789987654321000 | F13: PKP | G13: Art. 23 - Services | H13: 6120 | I13: Jl. Senopati No. 40, Jakarta | J13: Mandiri 1650098877 | K13: 30 | L13: =SUMIFS(tblPurchases[DPP (excl. VAT)],tblPurchases[Vendor ID],tblVendors[[#This Row],[Vendor ID]],tblPurchases[Date],"<="&PEnd) -> 124856000 | M13: =SUMIFS(tblPurchases[Total Payable],tblPurchases[Vendor ID],tblVendors[[#This Row],[Vendor ID]],tblPurchases[Date],"<="&PEnd,tblPurchases[Payment Date],">"&PEnd) -> 15033280
B14: V008 | C14: PT Ekspedisi Cepat Nusantara | D14: Shipping & Courier | E14: 0890987654321000 | F14: PKP | G14: Art. 23 - Services | H14: 6140 | I14: Jl. Daan Mogot Km 13, Jakarta | J14: BCA 2210334455 | K14: 14 | L14: =SUMIFS(tblPurchases[DPP (excl. VAT)],tblPurchases[Vendor ID],tblVendors[[#This Row],[Vendor ID]],tblPurchases[Date],"<="&PEnd) -> 102156000 | M14: =SUMIFS(tblPurchases[Total Payable],tblPurchases[Vendor ID],tblVendors[[#This Row],[Vendor ID]],tblPurchases[Date],"<="&PEnd,tblPurchases[Payment Date],">"&PEnd) -> 12300650
B15: V009 | C15: PT Utilitas Listrik & Telekom | D15: Utilities | E15: 0901987654321000 | F15: PKP | G15: None | H15: 6230 | I15: Jl. Gatot Subroto Kav. 18, Jakarta | J15: BNI 0123456789 | K15: 14 | L15: =SUMIFS(tblPurchases[DPP (excl. VAT)],tblPurchases[Vendor ID],tblVendors[[#This Row],[Vendor ID]],tblPurchases[Date],"<="&PEnd) -> 125473000 | M15: =SUMIFS(tblPurchases[Total Payable],tblPurchases[Vendor ID],tblVendors[[#This Row],[Vendor ID]],tblPurchases[Date],"<="&PEnd,tblPurchases[Payment Date],">"&PEnd) -> 0
B16: V010 | C16: KKP Mitra Pajak & Konsultan | D16: Professional Services | E16: 1012987654321000 | F16: PKP | G16: Art. 23 - Services | H16: 6280 | I16: Jl. Kuningan Barat No. 26, Jakarta | J16: BCA 3450778899 | K16: 14 | L16: =SUMIFS(tblPurchases[DPP (excl. VAT)],tblPurchases[Vendor ID],tblVendors[[#This Row],[Vendor ID]],tblPurchases[Date],"<="&PEnd) -> 140000000 | M16: =SUMIFS(tblPurchases[Total Payable],tblPurchases[Vendor ID],tblVendors[[#This Row],[Vendor ID]],tblPurchases[Date],"<="&PEnd,tblPurchases[Payment Date],">"&PEnd) -> 0
B17: V011 | C17: CV Teknik Servis Mandiri | D17: Repair & Maintenance | E17: 1123987654321000 | F17: Non-PKP | G17: Art. 23 - Services | H17: 6295 | I17: Jl. Fatmawati No. 66, Jakarta | J17: BRI 0567002233 | K17: 7 | L17: =SUMIFS(tblPurchases[DPP (excl. VAT)],tblPurchases[Vendor ID],tblVendors[[#This Row],[Vendor ID]],tblPurchases[Date],"<="&PEnd) -> 40738000 | M17: =SUMIFS(tblPurchases[Total Payable],tblPurchases[Vendor ID],tblVendors[[#This Row],[Vendor ID]],tblPurchases[Date],"<="&PEnd,tblPurchases[Payment Date],">"&PEnd) -> 0
B18: V012 | C18: Toko ATK Sentosa | D18: Office Supplies | E18: 1234987654321000 | F18: Non-PKP | G18: None | H18: 6270 | I18: Jl. Mangga Dua Raya No. 5, Jakarta | J18: BCA 4410223344 | K18: 0 | L18: =SUMIFS(tblPurchases[DPP (excl. VAT)],tblPurchases[Vendor ID],tblVendors[[#This Row],[Vendor ID]],tblPurchases[Date],"<="&PEnd) -> 29893000 | M18: =SUMIFS(tblPurchases[Total Payable],tblPurchases[Vendor ID],tblVendors[[#This Row],[Vendor ID]],tblPurchases[Date],"<="&PEnd,tblPurchases[Payment Date],">"&PEnd) -> 0
... B23: V017 | C23: Various Restaurants & Donations | D23: Entertainment & Donations | E23: 0000000000000000 | F23: Non-PKP | G23: None | H23: 6296 | I23: Various | J23: - | K23: 0 | L23: =SUMIFS(tblPurchases[DPP (excl. VAT)],tblPurchases[Vendor ID],tblVendors[[#This Row],[Vendor ID]],tblPurchases[Date],"<="&PEnd) -> 24449000 | M23: =SUMIFS(tblPurchases[Total Payable],tblPurchases[Vendor ID],tblVendors[[#This Row],[Vendor ID]],tblPurchases[Date],"<="&PEnd,tblPurchases[Payment Date],">"&PEnd) -> 0

Sheet Employees
B2: 🏠 HOME | E2: ◀ PREV | H2: NEXT ▶ | K2: ☰ MENU | M2: Journal | O2: Trial Bal. | Q2: Income St. | T2: Balance Sh. | W2: Tax Recon | Z2: Bank Recon | AC2: Controls
B4: EMPLOYEE MASTER
B5: Salary, PTKP and department feed the Payroll sheet automatically. TER category is derived from PTKP status (PP 58/2023).
B6: Employee ID | C6: Full Name | D6: Position | E6: Department | F6: Join Date | G6: NIK / NPWP | H6: PTKP Status | I6: Basic Salary | J6: Fixed Allowance | K6: Bank Account | L6: TER Category | M6: Gross Pay YTD | N6: PPh 21 YTD
B7: E001 | C7: Budi Santoso | D7: President Director | E7: G&A | F7: 43174 | G7: 3171010101800001 | H7: K/2 | I7: 25000000 | J7: 4000000 | K7: Mandiri 1230000001 | L7: =IF(OR(tblEmployees[[#This Row],[PTKP Status]]="TK/0",tblEmployees[[#This Row],[PTKP Status]]="TK/1",tblEmployees[[#This Row],[PTKP Status]]="K/0"),"A",IF(tblEmployees[[#This Row],[PTKP Status]]="K/3","C","B")) -> B | M7: =SUMIFS(tblPayroll[Gross Salary],tblPayroll[Employee ID],tblEmployees[[#This Row],[Employee ID]],tblPayroll[Period],"<="&CutOff) -> 319000000 | N7: =SUMIFS(tblPayroll[PPh 21],tblPayroll[Employee ID],tblEmployees[[#This Row],[Employee ID]],tblPayroll[Period],"<="&CutOff) -> 43734848
B8: E002 | C8: Siti Rahmawati | D8: Finance Director | E8: G&A | F8: 43222 | G8: 3171010202820002 | H8: K/1 | I8: 20000000 | J8: 3000000 | K8: Mandiri 1230000002 | L8: =IF(OR(tblEmployees[[#This Row],[PTKP Status]]="TK/0",tblEmployees[[#This Row],[PTKP Status]]="TK/1",tblEmployees[[#This Row],[PTKP Status]]="K/0"),"A",IF(tblEmployees[[#This Row],[PTKP Status]]="K/3","C","B")) -> B | M8: =SUMIFS(tblPayroll[Gross Salary],tblPayroll[Employee ID],tblEmployees[[#This Row],[Employee ID]],tblPayroll[Period],"<="&CutOff) -> 253000000 | N8: =SUMIFS(tblPayroll[PPh 21],tblPayroll[Employee ID],tblEmployees[[#This Row],[Employee ID]],tblPayroll[Period],"<="&CutOff) -> 27042116
B9: E003 | C9: Dewi Lestari | D9: Accounting Manager | E9: G&A | F9: 43507 | G9: 3171010303880003 | H9: TK/0 | I9: 15000000 | J9: 2000000 | K9: Mandiri 1230000003 | L9: =IF(OR(tblEmployees[[#This Row],[PTKP Status]]="TK/0",tblEmployees[[#This Row],[PTKP Status]]="TK/1",tblEmployees[[#This Row],[PTKP Status]]="K/0"),"A",IF(tblEmployees[[#This Row],[PTKP Status]]="K/3","C","B")) -> A | M9: =SUMIFS(tblPayroll[Gross Salary],tblPayroll[Employee ID],tblEmployees[[#This Row],[Employee ID]],tblPayroll[Period],"<="&CutOff) -> 187000000 | N9: =SUMIFS(tblPayroll[PPh 21],tblPayroll[Employee ID],tblEmployees[[#This Row],[Employee ID]],tblPayroll[Period],"<="&CutOff) -> 17491748
B10: E004 | C10: Agus Prasetyo | D10: Store Manager | E10: Selling | F10: 43647 | G10: 3171010404850004 | H10: K/1 | I10: 14000000 | J10: 2000000 | K10: Mandiri 1230000004 | L10: =IF(OR(tblEmployees[[#This Row],[PTKP Status]]="TK/0",tblEmployees[[#This Row],[PTKP Status]]="TK/1",tblEmployees[[#This Row],[PTKP Status]]="K/0"),"A",IF(tblEmployees[[#This Row],[PTKP Status]]="K/3","C","B")) -> B | M10: =SUMIFS(tblPayroll[Gross Salary],tblPayroll[Employee ID],tblEmployees[[#This Row],[Employee ID]],tblPayroll[Period],"<="&CutOff) -> 176000000 | N10: =SUMIFS(tblPayroll[PPh 21],tblPayroll[Employee ID],tblEmployees[[#This Row],[Employee ID]],tblPayroll[Period],"<="&CutOff) -> 14670464
B11: E005 | C11: Rina Kartika | D11: Marketing Lead | E11: Selling | F11: 43836 | G11: 3171010505900005 | H11: TK/0 | I11: 12000000 | J11: 1500000 | K11: Mandiri 1230000005 | L11: =IF(OR(tblEmployees[[#This Row],[PTKP Status]]="TK/0",tblEmployees[[#This Row],[PTKP Status]]="TK/1",tblEmployees[[#This Row],[PTKP Status]]="K/0"),"A",IF(tblEmployees[[#This Row],[PTKP Status]]="K/3","C","B")) -> A | M11: =SUMIFS(tblPayroll[Gross Salary],tblPayroll[Employee ID],tblEmployees[[#This Row],[Employee ID]],tblPayroll[Period],"<="&CutOff) -> 148500000 | N11: =SUMIFS(tblPayroll[PPh 21],tblPayroll[Employee ID],tblEmployees[[#This Row],[Employee ID]],tblPayroll[Period],"<="&CutOff) -> 10619385
B12: E006 | C12: Andi Saputra | D12: Tax & Finance Staff | E12: G&A | F12: 44256 | G12: 3171010606950006 | H12: TK/0 | I12: 8500000 | J12: 1000000 | K12: Mandiri 1230000006 | L12: =IF(OR(tblEmployees[[#This Row],[PTKP Status]]="TK/0",tblEmployees[[#This Row],[PTKP Status]]="TK/1",tblEmployees[[#This Row],[PTKP Status]]="K/0"),"A",IF(tblEmployees[[#This Row],[PTKP Status]]="K/3","C","B")) -> A | M12: =SUMIFS(tblPayroll[Gross Salary],tblPayroll[Employee ID],tblEmployees[[#This Row],[Employee ID]],tblPayroll[Period],"<="&CutOff) -> 104500000 | N12: =SUMIFS(tblPayroll[PPh 21],tblPayroll[Employee ID],tblEmployees[[#This Row],[Employee ID]],tblPayroll[Period],"<="&CutOff) -> 3342138
B13: E007 | C13: Fitri Handayani | D13: HR & GA Officer | E13: G&A | F13: 44424 | G13: 3171010707930007 | H13: K/0 | I13: 8000000 | J13: 1000000 | K13: Mandiri 1230000007 | L13: =IF(OR(tblEmployees[[#This Row],[PTKP Status]]="TK/0",tblEmployees[[#This Row],[PTKP Status]]="TK/1",tblEmployees[[#This Row],[PTKP Status]]="K/0"),"A",IF(tblEmployees[[#This Row],[PTKP Status]]="K/3","C","B")) -> A | M13: =SUMIFS(tblPayroll[Gross Salary],tblPayroll[Employee ID],tblEmployees[[#This Row],[Employee ID]],tblPayroll[Period],"<="&CutOff) -> 99000000 | N13: =SUMIFS(tblPayroll[PPh 21],tblPayroll[Employee ID],tblEmployees[[#This Row],[Employee ID]],tblPayroll[Period],"<="&CutOff) -> 2954547
B14: E008 | C14: Rizky Ramadhan | D14: Sales Supervisor | E14: Selling | F14: 44116 | G14: 3171010808910008 | H14: K/0 | I14: 9000000 | J14: 1500000 | K14: Mandiri 1230000008 | L14: =IF(OR(tblEmployees[[#This Row],[PTKP Status]]="TK/0",tblEmployees[[#This Row],[PTKP Status]]="TK/1",tblEmployees[[#This Row],[PTKP Status]]="K/0"),"A",IF(tblEmployees[[#This Row],[PTKP Status]]="K/3","C","B")) -> A | M14: =SUMIFS(tblPayroll[Gross Salary],tblPayroll[Employee ID],tblEmployees[[#This Row],[Employee ID]],tblPayroll[Period],"<="&CutOff) -> 115500000 | N14: =SUMIFS(tblPayroll[PPh 21],tblPayroll[Employee ID],tblEmployees[[#This Row],[Employee ID]],tblPayroll[Period],"<="&CutOff) -> 4896612
B15: E009 | C15: Nadia Putri | D15: Sales Associate | E15: Selling | F15: 44655 | G15: 3171010909990009 | H15: TK/0 | I15: 5800000 | J15: 700000 | K15: Mandiri 1230000009 | L15: =IF(OR(tblEmployees[[#This Row],[PTKP Status]]="TK/0",tblEmployees[[#This Row],[PTKP Status]]="TK/1",tblEmployees[[#This Row],[PTKP Status]]="K/0"),"A",IF(tblEmployees[[#This Row],[PTKP Status]]="K/3","C","B")) -> A | M15: =SUMIFS(tblPayroll[Gross Salary],tblPayroll[Employee ID],tblEmployees[[#This Row],[Employee ID]],tblPayroll[Period],"<="&CutOff) -> 71500000 | N15: =SUMIFS(tblPayroll[PPh 21],tblPayroll[Employee ID],tblEmployees[[#This Row],[Employee ID]],tblPayroll[Period],"<="&CutOff) -> 1429206
B16: E010 | C16: Dimas Pratama | D16: Sales Associate | E16: Selling | F16: 44935 | G16: 3171011010000010 | H16: TK/0 | I16: 5800000 | J16: 700000 | K16: Mandiri 1230000010 | L16: =IF(OR(tblEmployees[[#This Row],[PTKP Status]]="TK/0",tblEmployees[[#This Row],[PTKP Status]]="TK/1",tblEmployees[[#This Row],[PTKP Status]]="K/0"),"A",IF(tblEmployees[[#This Row],[PTKP Status]]="K/3","C","B")) -> A | M16: =SUMIFS(tblPayroll[Gross Salary],tblPayroll[Employee ID],tblEmployees[[#This Row],[Employee ID]],tblPayroll[Period],"<="&CutOff) -> 71500000 | N16: =SUMIFS(tblPayroll[PPh 21],tblPayroll[Employee ID],tblEmployees[[#This Row],[Employee ID]],tblPayroll[Period],"<="&CutOff) -> 1429206
B17: E011 | C17: Yusuf Hidayat | D17: Warehouse Supervisor | E17: Selling | F17: 43787 | G17: 3171011111870011 | H17: K/2 | I17: 7500000 | J17: 1000000 | K17: Mandiri 1230000011 | L17: =IF(OR(tblEmployees[[#This Row],[PTKP Status]]="TK/0",tblEmployees[[#This Row],[PTKP Status]]="TK/1",tblEmployees[[#This Row],[PTKP Status]]="K/0"),"A",IF(tblEmployees[[#This Row],[PTKP Status]]="K/3","C","B")) -> B | M17: =SUMIFS(tblPayroll[Gross Salary],tblPayroll[Employee ID],tblEmployees[[#This Row],[Employee ID]],tblPayroll[Period],"<="&CutOff) -> 93500000 | N17: =SUMIFS(tblPayroll[PPh 21],tblPayroll[Employee ID],tblEmployees[[#This Row],[Employee ID]],tblPayroll[Period],"<="&CutOff) -> 2016744
B18: E012 | C18: Lestari Wulandari | D18: Cashier | E18: Selling | F18: 44725 | G18: 3171011212970012 | H18: TK/1 | I18: 5600000 | J18: 600000 | K18: Mandiri 1230000012 | L18: =IF(OR(tblEmployees[[#This Row],[PTKP Status]]="TK/0",tblEmployees[[#This Row],[PTKP Status]]="TK/1",tblEmployees[[#This Row],[PTKP Status]]="K/0"),"A",IF(tblEmployees[[#This Row],[PTKP Status]]="K/3","C","B")) -> A | M18: =SUMIFS(tblPayroll[Gross Salary],tblPayroll[Employee ID],tblEmployees[[#This Row],[Employee ID]],tblPayroll[Period],"<="&CutOff) -> 68200000 | N18: =SUMIFS(tblPayroll[PPh 21],tblPayroll[Employee ID],tblEmployees[[#This Row],[Employee ID]],tblPayroll[Period],"<="&CutOff) -> 1217409
... B21: E015 | C21: Hendra Wijaya | D21: IT Support | E21: G&A | F21: 44466 | G21: 3171011503940015 | H21: TK/0 | I21: 9500000 | J21: 1000000 | K21: Mandiri 1230000015 | L21: =IF(OR(tblEmployees[[#This Row],[PTKP Status]]="TK/0",tblEmployees[[#This Row],[PTKP Status]]="TK/1",tblEmployees[[#This Row],[PTKP Status]]="K/0"),"A",IF(tblEmployees[[#This Row],[PTKP Status]]="K/3","C","B")) -> A | M21: =SUMIFS(tblPayroll[Gross Salary],tblPayroll[Employee ID],tblEmployees[[#This Row],[Employee ID]],tblPayroll[Period],"<="&CutOff) -> 115500000 | N21: =SUMIFS(tblPayroll[PPh 21],tblPayroll[Employee ID],tblEmployees[[#This Row],[Employee ID]],tblPayroll[Period],"<="&CutOff) -> 4896612

Sheet Products
B2: 🏠 HOME | E2: ◀ PREV | G2: NEXT ▶ | I2: ☰ MENU | K2: Journal | O2: Trial Bal. | R2: Income St. | U2: Balance Sh. | X2: Tax Recon | AA2: Bank Recon | AD2: Controls
B4: PRODUCT / SERVICE MASTER
B5: Names, categories & units follow the selected industry. Prices & unit costs (blue) are editable.
B6: Code | C6: Product / Service Name | D6: Category Group | E6: Category | F6: Unit | G6: Selling Price (excl. VAT) | H6: Unit Cost | I6: Gross Margin % | J6: Qty Sold YTD | K6: Sales YTD | O6: Channel Code | P6: Channel Name
B7: P01 | C7: =_xlfn.XLOOKUP("Product "&tblProducts[[#This Row],[Code]],'Industry Profile'!$B$18:$B$27,'Industry Profile'!$C$18:$C$27) -> Socks & Accessories | D7: 1 | E7: {=INDEX('Industry Profile'!$C$12:$C$14,tblProducts[[#This Row],[Category Group]])} -> Accessories & Basics | F7: =IP_Unit -> pcs | G7: 45000 | H7: 24000 | I7: =IFERROR(1-tblProducts[[#This Row],[Unit Cost]]/tblProducts[[#This Row],[Selling Price (excl. VAT)]],0) -> 0.46666667 | J7: =SUMIFS(tblSales[Qty],tblSales[Product Code],tblProducts[[#This Row],[Code]],tblSales[Date],"<="&PEnd) -> 15222 | K7: =SUMIFS(tblSales[DPP (excl. VAT)],tblSales[Product Code],tblProducts[[#This Row],[Code]],tblSales[Date],"<="&PEnd) -> 684990000 | O7: CH1 | P7: ='Industry Profile'!C15 -> In-store
B8: P02 | C8: =_xlfn.XLOOKUP("Product "&tblProducts[[#This Row],[Code]],'Industry Profile'!$B$18:$B$27,'Industry Profile'!$C$18:$C$27) -> Premium Basic T-shirt | D8: 1 | E8: {=INDEX('Industry Profile'!$C$12:$C$14,tblProducts[[#This Row],[Category Group]])} -> Accessories & Basics | F8: =IP_Unit -> pcs | G8: 65000 | H8: 37000 | I8: =IFERROR(1-tblProducts[[#This Row],[Unit Cost]]/tblProducts[[#This Row],[Selling Price (excl. VAT)]],0) -> 0.43076923 | J8: =SUMIFS(tblSales[Qty],tblSales[Product Code],tblProducts[[#This Row],[Code]],tblSales[Date],"<="&PEnd) -> 13201 | K8: =SUMIFS(tblSales[DPP (excl. VAT)],tblSales[Product Code],tblProducts[[#This Row],[Code]],tblSales[Date],"<="&PEnd) -> 858065000 | O8: CH2 | P8: ='Industry Profile'!C16 -> Marketplace
B9: P03 | C9: =_xlfn.XLOOKUP("Product "&tblProducts[[#This Row],[Code]],'Industry Profile'!$B$18:$B$27,'Industry Profile'!$C$18:$C$27) -> Casual Shorts | D9: 1 | E9: {=INDEX('Industry Profile'!$C$12:$C$14,tblProducts[[#This Row],[Category Group]])} -> Accessories & Basics | F9: =IP_Unit -> pcs | G9: 85000 | H9: 50000 | I9: =IFERROR(1-tblProducts[[#This Row],[Unit Cost]]/tblProducts[[#This Row],[Selling Price (excl. VAT)]],0) -> 0.41176471 | J9: =SUMIFS(tblSales[Qty],tblSales[Product Code],tblProducts[[#This Row],[Code]],tblSales[Date],"<="&PEnd) -> 13718 | K9: =SUMIFS(tblSales[DPP (excl. VAT)],tblSales[Product Code],tblProducts[[#This Row],[Code]],tblSales[Date],"<="&PEnd) -> 1166030000 | O9: CH3 | P9: ='Industry Profile'!C17 -> Website & Social Media
B10: P04 | C10: =_xlfn.XLOOKUP("Product "&tblProducts[[#This Row],[Code]],'Industry Profile'!$B$18:$B$27,'Industry Profile'!$C$18:$C$27) -> Casual Shirt | D10: 2 | E10: {=INDEX('Industry Profile'!$C$12:$C$14,tblProducts[[#This Row],[Category Group]])} -> Apparel & Footwear | F10: =IP_Unit -> pcs | G10: 120000 | H10: 72000 | I10: =IFERROR(1-tblProducts[[#This Row],[Unit Cost]]/tblProducts[[#This Row],[Selling Price (excl. VAT)]],0) -> 0.4 | J10: =SUMIFS(tblSales[Qty],tblSales[Product Code],tblProducts[[#This Row],[Code]],tblSales[Date],"<="&PEnd) -> 11669 | K10: =SUMIFS(tblSales[DPP (excl. VAT)],tblSales[Product Code],tblProducts[[#This Row],[Code]],tblSales[Date],"<="&PEnd) -> 1400280000
B11: P05 | C11: =_xlfn.XLOOKUP("Product "&tblProducts[[#This Row],[Code]],'Industry Profile'!$B$18:$B$27,'Industry Profile'!$C$18:$C$27) -> Chino Pants | D11: 2 | E11: {=INDEX('Industry Profile'!$C$12:$C$14,tblProducts[[#This Row],[Category Group]])} -> Apparel & Footwear | F11: =IP_Unit -> pcs | G11: 150000 | H11: 88000 | I11: =IFERROR(1-tblProducts[[#This Row],[Unit Cost]]/tblProducts[[#This Row],[Selling Price (excl. VAT)]],0) -> 0.41333333 | J11: =SUMIFS(tblSales[Qty],tblSales[Product Code],tblProducts[[#This Row],[Code]],tblSales[Date],"<="&PEnd) -> 9809 | K11: =SUMIFS(tblSales[DPP (excl. VAT)],tblSales[Product Code],tblProducts[[#This Row],[Code]],tblSales[Date],"<="&PEnd) -> 1471350000
B12: P06 | C12: =_xlfn.XLOOKUP("Product "&tblProducts[[#This Row],[Code]],'Industry Profile'!$B$18:$B$27,'Industry Profile'!$C$18:$C$27) -> Sneakers | D12: 2 | E12: {=INDEX('Industry Profile'!$C$12:$C$14,tblProducts[[#This Row],[Category Group]])} -> Apparel & Footwear | F12: =IP_Unit -> pcs | G12: 250000 | H12: 155000 | I12: =IFERROR(1-tblProducts[[#This Row],[Unit Cost]]/tblProducts[[#This Row],[Selling Price (excl. VAT)]],0) -> 0.38 | J12: =SUMIFS(tblSales[Qty],tblSales[Product Code],tblProducts[[#This Row],[Code]],tblSales[Date],"<="&PEnd) -> 4142 | K12: =SUMIFS(tblSales[DPP (excl. VAT)],tblSales[Product Code],tblProducts[[#This Row],[Code]],tblSales[Date],"<="&PEnd) -> 1035500000 | O12: Payment Method | P12: Account Code
B13: P07 | C13: =_xlfn.XLOOKUP("Product "&tblProducts[[#This Row],[Code]],'Industry Profile'!$B$18:$B$27,'Industry Profile'!$C$18:$C$27) -> Bomber Jacket | D13: 2 | E13: {=INDEX('Industry Profile'!$C$12:$C$14,tblProducts[[#This Row],[Category Group]])} -> Apparel & Footwear | F13: =IP_Unit -> pcs | G13: 350000 | H13: 210000 | I13: =IFERROR(1-tblProducts[[#This Row],[Unit Cost]]/tblProducts[[#This Row],[Selling Price (excl. VAT)]],0) -> 0.4 | J13: =SUMIFS(tblSales[Qty],tblSales[Product Code],tblProducts[[#This Row],[Code]],tblSales[Date],"<="&PEnd) -> 3306 | K13: =SUMIFS(tblSales[DPP (excl. VAT)],tblSales[Product Code],tblProducts[[#This Row],[Code]],tblSales[Date],"<="&PEnd) -> 1157100000 | O13: Cash | P13: 1110
B14: P08 | C14: =_xlfn.XLOOKUP("Product "&tblProducts[[#This Row],[Code]],'Industry Profile'!$B$18:$B$27,'Industry Profile'!$C$18:$C$27) -> Backpack | D14: 3 | E14: {=INDEX('Industry Profile'!$C$12:$C$14,tblProducts[[#This Row],[Category Group]])} -> Bags & Gadgets | F14: =IP_Unit -> pcs | G14: 500000 | H14: 290000 | I14: =IFERROR(1-tblProducts[[#This Row],[Unit Cost]]/tblProducts[[#This Row],[Selling Price (excl. VAT)]],0) -> 0.42 | J14: =SUMIFS(tblSales[Qty],tblSales[Product Code],tblProducts[[#This Row],[Code]],tblSales[Date],"<="&PEnd) -> 2531 | K14: =SUMIFS(tblSales[DPP (excl. VAT)],tblSales[Product Code],tblProducts[[#This Row],[Code]],tblSales[Date],"<="&PEnd) -> 1265500000 | O14: QRIS / Transfer | P14: 1120
B15: P09 | C15: =_xlfn.XLOOKUP("Product "&tblProducts[[#This Row],[Code]],'Industry Profile'!$B$18:$B$27,'Industry Profile'!$C$18:$C$27) -> Smartwatch | D15: 3 | E15: {=INDEX('Industry Profile'!$C$12:$C$14,tblProducts[[#This Row],[Category Group]])} -> Bags & Gadgets | F15: =IP_Unit -> pcs | G15: 850000 | H15: 560000 | I15: =IFERROR(1-tblProducts[[#This Row],[Unit Cost]]/tblProducts[[#This Row],[Selling Price (excl. VAT)]],0) -> 0.34117647 | J15: =SUMIFS(tblSales[Qty],tblSales[Product Code],tblProducts[[#This Row],[Code]],tblSales[Date],"<="&PEnd) -> 1080 | K15: =SUMIFS(tblSales[DPP (excl. VAT)],tblSales[Product Code],tblProducts[[#This Row],[Code]],tblSales[Date],"<="&PEnd) -> 918000000 | O15: Credit (Term) | P15: 1210
B16: P10 | C16: =_xlfn.XLOOKUP("Product "&tblProducts[[#This Row],[Code]],'Industry Profile'!$B$18:$B$27,'Industry Profile'!$C$18:$C$27) -> Wireless Earbuds Pro | D16: 3 | E16: {=INDEX('Industry Profile'!$C$12:$C$14,tblProducts[[#This Row],[Category Group]])} -> Bags & Gadgets | F16: =IP_Unit -> pcs | G16: 1250000 | H16: 820000 | I16: =IFERROR(1-tblProducts[[#This Row],[Unit Cost]]/tblProducts[[#This Row],[Selling Price (excl. VAT)]],0) -> 0.344 | J16: =SUMIFS(tblSales[Qty],tblSales[Product Code],tblProducts[[#This Row],[Code]],tblSales[Date],"<="&PEnd) -> 1115 | K16: =SUMIFS(tblSales[DPP (excl. VAT)],tblSales[Product Code],tblProducts[[#This Row],[Code]],tblSales[Date],"<="&PEnd) -> 1393750000

Sheet Sales
B2: 🏠 HOME | D2: ◀ PREV | G2: NEXT ▶ | I2: ☰ MENU | L2: Journal | N2: Trial Bal. | P2: Income St. | S2: Balance Sh. | V2: Tax Recon | Y2: Bank Recon | AB2: Controls
B4: SALES SUB-LEDGER (DAILY INVOICE LINES)
B5: Blue = inputs. Prices, VAT (12% × DPP 11/12) and COGS calculate automatically. Monthly totals post to the General Journal (Source = Auto-Sales).
B6: Date | C6: Invoice No | D6: Customer ID | E6: Customer Name | F6: Product Code | G6: Product / Service | H6: Category | I6: Qty | J6: Unit Price | K6: DPP (excl. VAT) | L6: Output VAT | M6: Total incl. VAT | N6: COGS | O6: Payment Method | P6: Channel Code | Q6: Channel | R6: Month
